Workbook

Sheet G2 MT Reading Scoresheet
A1: CRLA3v3
A3: ASSESSMENT TYPE
A4: School ID: | D4: Total Enrolment | F4: =D6+E6 -> 0 | G4: Total Assessed : | I4: =COUNTIF(F11:F110,"<>") -> 0
A5: Schoo Name: | D5: Male | E5: Female | F5: Assessment Part 1 (Word Recognition and Sentences Reading) | J5: WORDS SCORE 0 to 10 – Full Refresher 11 to 16 – Moderate Refresher SENTENCE SCORE 17 to 26 – Light Refresher 27 to 30 – Grade Ready | K5: Assessment Part 2 (Reading Fluency and Comprehension)
A6: Teacher:
A7: Grade: | C7: Grade 2 | D7: Total Words per Story | F7: Task 1 – Write the number of Words sounded out correctly | G7: Rhymes (Task 2) If task 1 score is 0 to 6 | H7: Sentence (Task 2) If task 1 score is 7 to 10 Task 2L=10 | I7: Total Score = Task 1 Score + Task 2L+Task 2H Score | K7: Total Words Per Story | L7: Story 1 | M7: =_xlfn.IFNA(IF(X9=1,Y9,IF(D9>0,D9,95)),"") -> 96 | N7: Story 2 | P7: =_xlfn.IFNA(IF(X9=1,Z9,IF(E9>0,E9,95)),"") -> 95
A8: Section: | D8: Story 1 | E8: Story 2 | K8: Story Number 1 or 2 | L8: Total Reading Miscues | M8: Number of words read within 2 mins | N8: Total Time Used in Reading (Max : 2 Mins) | P8: Number of Words per Minute (WPM)
A9: Language: | C9: Tagalog | X9: =IF(_xlfn.IFNA(VLOOKUP($C$9,List!$G$2:$M$20,1,0),"")=C9,1,0) -> 1 | Y9: =VLOOKUP($C$9,List!$G$2:$M$20,4,0) -> 96 | Z9: =VLOOKUP($C$9,List!$G$2:$M$20,7,0) -> 95
A10: S/N | B10: LRN | C10: Name of Learner | D10: Sex | E10: Date of Asessment | F10: Task 1 (10) | G10: Task 2L Words (10) | H10: Task 2H Sentences (10) | I10: Total Score | J10: Part 1 Reading Level | K10: Story Number | L10: Number of Miscue | M10: Words Read | N10: Total Mins Secs | P10: WPM | Q10: % of Correct Words Read | R10: Total Correct Answer | S10: Leaner Experience (Rating 1-5) | T10: Observation Level | U10: READING PROFILE | V10: Remarks
A11: 1 | I11: =IF(AND(F11="",G11=""),"",IF(F11<7,F11+G11,F11+10+H11)) | J11: =IF(I11="","",IF(F11<7,IF(I11<=10,"Full Refresher","Moderate Refresher"),IF(I11<27,"Light Refresher","Grade Ready"))) | M11: =IF($C$9<>"",IF(OR(K11=1, K11=2),IF(K11=1,M$7-L11,$P$7-L11),""),"") | P11: =IF(AND(K11>0,M11>0,OR(N11>0,O11>0)),(M11/((N11*60)+O11))*60,"") | Q11: =IFERROR(IF(OR(K11=1, K11=2),IF(K11=1,M11/$M$7,M11/$P$7),""),"") | U11: =IF(J11<>"",IF(J11="Full Refresher","Low Emerging Reader",IF(AND(K11>0,Q11<>""),IF(OR(Q11<=25%,AND(Q11>25%,Q11<=50%, R11=0)),"High Emerging Reader",IF(OR(AND(Q11>25%,Q11<51%, R11>=1),AND(Q11>50%,Q11<76%,R11<=2)),"Developing Reader",IF(OR(AND(Q11>=51%, Q11<76%,R11>=3),AND(Q11>75%,R11<=4)),"Transitioning Reader",IF(AND(Q11>75%,R11>=5),"Reading At Grade Level","")))),"")),"") | Y11: =IF(C11<>"",R11/6,"")
A12: 2 | I12: =IF(AND(F12="",G12=""),"",IF(F12<7,F12+G12,F12+10+H12)) | J12: =IF(I12="","",IF(F12<7,IF(I12<=10,"Full Refresher","Moderate Refresher"),IF(I12<27,"Light Refresher","Grade Ready"))) | M12: =IF($C$9<>"",IF(OR(K12=1, K12=2),IF(K12=1,M$7-L12,$P$7-L12),""),"") | P12: =IF(AND(K12>0,M12>0,OR(N12>0,O12>0)),(M12/((N12*60)+O12))*60,"") | Q12: =IFERROR(IF(OR(K12=1, K12=2),IF(K12=1,M12/$M$7,M12/$P$7),""),"") | U12: =IF(J12<>"",IF(J12="Full Refresher","Low Emerging Reader",IF(AND(K12>0,Q12<>""),IF(OR(Q12<=25%,AND(Q12>25%,Q12<=50%, R12=0)),"High Emerging Reader",IF(OR(AND(Q12>25%,Q12<51%, R12>=1),AND(Q12>50%,Q12<76%,R12<=2)),"Developing Reader",IF(OR(AND(Q12>=51%, Q12<76%,R12>=3),AND(Q12>75%,R12<=4)),"Transitioning Reader",IF(AND(Q12>75%,R12>=5),"Reading At Grade Level","")))),"")),"") | Y12: =IF(C12<>"",R12/6,"")
A13: 3 | I13: =IF(AND(F13="",G13=""),"",IF(F13<7,F13+G13,F13+10+H13)) | J13: =IF(I13="","",IF(F13<7,IF(I13<=10,"Full Refresher","Moderate Refresher"),IF(I13<27,"Light Refresher","Grade Ready"))) | M13: =IF($C$9<>"",IF(OR(K13=1, K13=2),IF(K13=1,M$7-L13,$P$7-L13),""),"") | P13: =IF(AND(K13>0,M13>0,OR(N13>0,O13>0)),(M13/((N13*60)+O13))*60,"") | Q13: =IFERROR(IF(OR(K13=1, K13=2),IF(K13=1,M13/$M$7,M13/$P$7),""),"") | U13: =IF(J13<>"",IF(J13="Full Refresher","Low Emerging Reader",IF(AND(K13>0,Q13<>""),IF(OR(Q13<=25%,AND(Q13>25%,Q13<=50%, R13=0)),"High Emerging Reader",IF(OR(AND(Q13>25%,Q13<51%, R13>=1),AND(Q13>50%,Q13<76%,R13<=2)),"Developing Reader",IF(OR(AND(Q13>=51%, Q13<76%,R13>=3),AND(Q13>75%,R13<=4)),"Transitioning Reader",IF(AND(Q13>75%,R13>=5),"Reading At Grade Level","")))),"")),"") | Y13: =IF(C13<>"",R13/6,"")
A14: 4 | I14: =IF(AND(F14="",G14=""),"",IF(F14<7,F14+G14,F14+10+H14)) | J14: =IF(I14="","",IF(F14<7,IF(I14<=10,"Full Refresher","Moderate Refresher"),IF(I14<27,"Light Refresher","Grade Ready"))) | M14: =IF($C$9<>"",IF(OR(K14=1, K14=2),IF(K14=1,M$7-L14,$P$7-L14),""),"") | P14: =IF(AND(K14>0,M14>0,OR(N14>0,O14>0)),(M14/((N14*60)+O14))*60,"") | Q14: =IFERROR(IF(OR(K14=1, K14=2),IF(K14=1,M14/$M$7,M14/$P$7),""),"") | U14: =IF(J14<>"",IF(J14="Full Refresher","Low Emerging Reader",IF(AND(K14>0,Q14<>""),IF(OR(Q14<=25%,AND(Q14>25%,Q14<=50%, R14=0)),"High Emerging Reader",IF(OR(AND(Q14>25%,Q14<51%, R14>=1),AND(Q14>50%,Q14<76%,R14<=2)),"Developing Reader",IF(OR(AND(Q14>=51%, Q14<76%,R14>=3),AND(Q14>75%,R14<=4)),"Transitioning Reader",IF(AND(Q14>75%,R14>=5),"Reading At Grade Level","")))),"")),"") | Y14: =IF(C14<>"",R14/6,"")
A15: 5 | I15: =IF(AND(F15="",G15=""),"",IF(F15<7,F15+G15,F15+10+H15)) | J15: =IF(I15="","",IF(F15<7,IF(I15<=10,"Full Refresher","Moderate Refresher"),IF(I15<27,"Light Refresher","Grade Ready"))) | M15: =IF($C$9<>"",IF(OR(K15=1, K15=2),IF(K15=1,M$7-L15,$P$7-L15),""),"") | P15: =IF(AND(K15>0,M15>0,OR(N15>0,O15>0)),(M15/((N15*60)+O15))*60,"") | Q15: =IFERROR(IF(OR(K15=1, K15=2),IF(K15=1,M15/$M$7,M15/$P$7),""),"") | U15: =IF(J15<>"",IF(J15="Full Refresher","Low Emerging Reader",IF(AND(K15>0,Q15<>""),IF(OR(Q15<=25%,AND(Q15>25%,Q15<=50%, R15=0)),"High Emerging Reader",IF(OR(AND(Q15>25%,Q15<51%, R15>=1),AND(Q15>50%,Q15<76%,R15<=2)),"Developing Reader",IF(OR(AND(Q15>=51%, Q15<76%,R15>=3),AND(Q15>75%,R15<=4)),"Transitioning Reader",IF(AND(Q15>75%,R15>=5),"Reading At Grade Level","")))),"")),"") | Y15: =IF(C15<>"",R15/6,"")
A16: 6 | I16: =IF(AND(F16="",G16=""),"",IF(F16<7,F16+G16,F16+10+H16)) | J16: =IF(I16="","",IF(F16<7,IF(I16<=10,"Full Refresher","Moderate Refresher"),IF(I16<27,"Light Refresher","Grade Ready"))) | M16: =IF($C$9<>"",IF(OR(K16=1, K16=2),IF(K16=1,M$7-L16,$P$7-L16),""),"") | P16: =IF(AND(K16>0,M16>0,OR(N16>0,O16>0)),(M16/((N16*60)+O16))*60,"") | Q16: =IFERROR(IF(OR(K16=1, K16=2),IF(K16=1,M16/$M$7,M16/$P$7),""),"") | U16: =IF(J16<>"",IF(J16="Full Refresher","Low Emerging Reader",IF(AND(K16>0,Q16<>""),IF(OR(Q16<=25%,AND(Q16>25%,Q16<=50%, R16=0)),"High Emerging Reader",IF(OR(AND(Q16>25%,Q16<51%, R16>=1),AND(Q16>50%,Q16<76%,R16<=2)),"Developing Reader",IF(OR(AND(Q16>=51%, Q16<76%,R16>=3),AND(Q16>75%,R16<=4)),"Transitioning Reader",IF(AND(Q16>75%,R16>=5),"Reading At Grade Level","")))),"")),"") | Y16: =IF(C16<>"",R16/6,"")
A17: 7 | I17: =IF(AND(F17="",G17=""),"",IF(F17<7,F17+G17,F17+10+H17)) | J17: =IF(I17="","",IF(F17<7,IF(I17<=10,"Full Refresher","Moderate Refresher"),IF(I17<27,"Light Refresher","Grade Ready"))) | M17: =IF($C$9<>"",IF(OR(K17=1, K17=2),IF(K17=1,M$7-L17,$P$7-L17),""),"") | P17: =IF(AND(K17>0,M17>0,OR(N17>0,O17>0)),(M17/((N17*60)+O17))*60,"") | Q17: =IFERROR(IF(OR(K17=1, K17=2),IF(K17=1,M17/$M$7,M17/$P$7),""),"") | U17: =IF(J17<>"",IF(J17="Full Refresher","Low Emerging Reader",IF(AND(K17>0,Q17<>""),IF(OR(Q17<=25%,AND(Q17>25%,Q17<=50%, R17=0)),"High Emerging Reader",IF(OR(AND(Q17>25%,Q17<51%, R17>=1),AND(Q17>50%,Q17<76%,R17<=2)),"Developing Reader",IF(OR(AND(Q17>=51%, Q17<76%,R17>=3),AND(Q17>75%,R17<=4)),"Transitioning Reader",IF(AND(Q17>75%,R17>=5),"Reading At Grade Level","")))),"")),"") | Y17: =IF(C17<>"",R17/6,"")
A18: 8 | I18: =IF(AND(F18="",G18=""),"",IF(F18<7,F18+G18,F18+10+H18)) | J18: =IF(I18="","",IF(F18<7,IF(I18<=10,"Full Refresher","Moderate Refresher"),IF(I18<27,"Light Refresher","Grade Ready"))) | M18: =IF($C$9<>"",IF(OR(K18=1, K18=2),IF(K18=1,M$7-L18,$P$7-L18),""),"") | P18: =IF(AND(K18>0,M18>0,OR(N18>0,O18>0)),(M18/((N18*60)+O18))*60,"") | Q18: =IFERROR(IF(OR(K18=1, K18=2),IF(K18=1,M18/$M$7,M18/$P$7),""),"") | U18: =IF(J18<>"",IF(J18="Full Refresher","Low Emerging Reader",IF(AND(K18>0,Q18<>""),IF(OR(Q18<=25%,AND(Q18>25%,Q18<=50%, R18=0)),"High Emerging Reader",IF(OR(AND(Q18>25%,Q18<51%, R18>=1),AND(Q18>50%,Q18<76%,R18<=2)),"Developing Reader",IF(OR(AND(Q18>=51%, Q18<76%,R18>=3),AND(Q18>75%,R18<=4)),"Transitioning Reader",IF(AND(Q18>75%,R18>=5),"Reading At Grade Level","")))),"")),"") | Y18: =IF(C18<>"",R18/6,"")
A19: 9 | I19: =IF(AND(F19="",G19=""),"",IF(F19<7,F19+G19,F19+10+H19)) | J19: =IF(I19="","",IF(F19<7,IF(I19<=10,"Full Refresher","Moderate Refresher"),IF(I19<27,"Light Refresher","Grade Ready"))) | M19: =IF($C$9<>"",IF(OR(K19=1, K19=2),IF(K19=1,M$7-L19,$P$7-L19),""),"") | P19: =IF(AND(K19>0,M19>0,OR(N19>0,O19>0)),(M19/((N19*60)+O19))*60,"") | Q19: =IFERROR(IF(OR(K19=1, K19=2),IF(K19=1,M19/$M$7,M19/$P$7),""),"") | U19: =IF(J19<>"",IF(J19="Full Refresher","Low Emerging Reader",IF(AND(K19>0,Q19<>""),IF(OR(Q19<=25%,AND(Q19>25%,Q19<=50%, R19=0)),"High Emerging Reader",IF(OR(AND(Q19>25%,Q19<51%, R19>=1),AND(Q19>50%,Q19<76%,R19<=2)),"Developing Reader",IF(OR(AND(Q19>=51%, Q19<76%,R19>=3),AND(Q19>75%,R19<=4)),"Transitioning Reader",IF(AND(Q19>75%,R19>=5),"Reading At Grade Level","")))),"")),"") | Y19: =IF(C19<>"",R19/6,"")
A20: 10 | I20: =IF(AND(F20="",G20=""),"",IF(F20<7,F20+G20,F20+10+H20)) | J20: =IF(I20="","",IF(F20<7,IF(I20<=10,"Full Refresher","Moderate Refresher"),IF(I20<27,"Light Refresher","Grade Ready"))) | M20: =IF($C$9<>"",IF(OR(K20=1, K20=2),IF(K20=1,M$7-L20,$P$7-L20),""),"") | P20: =IF(AND(K20>0,M20>0,OR(N20>0,O20>0)),(M20/((N20*60)+O20))*60,"") | Q20: =IFERROR(IF(OR(K20=1, K20=2),IF(K20=1,M20/$M$7,M20/$P$7),""),"") | U20: =IF(J20<>"",IF(J20="Full Refresher","Low Emerging Reader",IF(AND(K20>0,Q20<>""),IF(OR(Q20<=25%,AND(Q20>25%,Q20<=50%, R20=0)),"High Emerging Reader",IF(OR(AND(Q20>25%,Q20<51%, R20>=1),AND(Q20>50%,Q20<76%,R20<=2)),"Developing Reader",IF(OR(AND(Q20>=51%, Q20<76%,R20>=3),AND(Q20>75%,R20<=4)),"Transitioning Reader",IF(AND(Q20>75%,R20>=5),"Reading At Grade Level","")))),"")),"") | Y20: =IF(C20<>"",R20/6,"")
A21: 11 | I21: =IF(AND(F21="",G21=""),"",IF(F21<7,F21+G21,F21+10+H21)) | J21: =IF(I21="","",IF(F21<7,IF(I21<=10,"Full Refresher","Moderate Refresher"),IF(I21<27,"Light Refresher","Grade Ready"))) | M21: =IF($C$9<>"",IF(OR(K21=1, K21=2),IF(K21=1,M$7-L21,$P$7-L21),""),"") | P21: =IF(AND(K21>0,M21>0,OR(N21>0,O21>0)),(M21/((N21*60)+O21))*60,"") | Q21: =IFERROR(IF(OR(K21=1, K21=2),IF(K21=1,M21/$M$7,M21/$P$7),""),"") | U21: =IF(J21<>"",IF(J21="Full Refresher","Low Emerging Reader",IF(AND(K21>0,Q21<>""),IF(OR(Q21<=25%,AND(Q21>25%,Q21<=50%, R21=0)),"High Emerging Reader",IF(OR(AND(Q21>25%,Q21<51%, R21>=1),AND(Q21>50%,Q21<76%,R21<=2)),"Developing Reader",IF(OR(AND(Q21>=51%, Q21<76%,R21>=3),AND(Q21>75%,R21<=4)),"Transitioning Reader",IF(AND(Q21>75%,R21>=5),"Reading At Grade Level","")))),"")),"") | Y21: =IF(C21<>"",R21/6,"")
A22: 12 | I22: =IF(AND(F22="",G22=""),"",IF(F22<7,F22+G22,F22+10+H22)) | J22: =IF(I22="","",IF(F22<7,IF(I22<=10,"Full Refresher","Moderate Refresher"),IF(I22<27,"Light Refresher","Grade Ready"))) | M22: =IF($C$9<>"",IF(OR(K22=1, K22=2),IF(K22=1,M$7-L22,$P$7-L22),""),"") | P22: =IF(AND(K22>0,M22>0,OR(N22>0,O22>0)),(M22/((N22*60)+O22))*60,"") | Q22: =IFERROR(IF(OR(K22=1, K22=2),IF(K22=1,M22/$M$7,M22/$P$7),""),"") | U22: =IF(J22<>"",IF(J22="Full Refresher","Low Emerging Reader",IF(AND(K22>0,Q22<>""),IF(OR(Q22<=25%,AND(Q22>25%,Q22<=50%, R22=0)),"High Emerging Reader",IF(OR(AND(Q22>25%,Q22<51%, R22>=1),AND(Q22>50%,Q22<76%,R22<=2)),"Developing Reader",IF(OR(AND(Q22>=51%, Q22<76%,R22>=3),AND(Q22>75%,R22<=4)),"Transitioning Reader",IF(AND(Q22>75%,R22>=5),"Reading At Grade Level","")))),"")),"") | Y22: =IF(C22<>"",R22/6,"")
... A69: 59 | I69: =IF(AND(F69="",G69=""),"",IF(F69<7,F69+G69,F69+10+H69)) | J69: =IF(I69="","",IF(F69<7,IF(I69<=10,"Full Refresher","Moderate Refresher"),IF(I69<27,"Light Refresher","Grade Ready"))) | M69: =IF($C$9<>"",IF(OR(K69=1, K69=2),IF(K69=1,M$7-L69,$P$7-L69),""),"") | P69: =IF(AND(K69>0,M69>0,OR(N69>0,O69>0)),(M69/((N69*60)+O69))*60,"") | Q69: =IFERROR(IF(OR(K69=1, K69=2),IF(K69=1,M69/$M$7,M69/$P$7),""),"") | U69: =IF(J69<>"",IF(J69="Full Refresher","Low Emerging Reader",IF(AND(K69>0,Q69<>""),IF(OR(Q69<=25%,AND(Q69>25%,Q69<=50%, R69=0)),"High Emerging Reader",IF(OR(AND(Q69>25%,Q69<51%, R69>=1),AND(Q69>50%,Q69<76%,R69<=2)),"Developing Reader",IF(OR(AND(Q69>=51%, Q69<76%,R69>=3),AND(Q69>75%,R69<=4)),"Transitioning Reader",IF(AND(Q69>75%,R69>=5),"Reading At Grade Level","")))),"")),"") | Y69: =IF(C69<>"",R69/6,"")
A70: =A69+1 -> 60 | I70: =IF(AND(F70="",G70=""),"",IF(F70<7,F70+G70,F70+10+H70)) | J70: =IF(I70="","",IF(F70<7,IF(I70<=10,"Full Refresher","Moderate Refresher"),IF(I70<27,"Light Refresher","Grade Ready"))) | M70: =IF($C$9<>"",IF(OR(K70=1, K70=2),IF(K70=1,M$7-L70,$P$7-L70),""),"") | P70: =IF(AND(K70>0,M70>0,OR(N70>0,O70>0)),(M70/((N70*60)+O70))*60,"") | Q70: =IFERROR(IF(OR(K70=1, K70=2),IF(K70=1,M70/$M$7,M70/$P$7),""),"") | U70: =IF(J70<>"",IF(J70="Full Refresher","Low Emerging Reader",IF(AND(K70>0,Q70<>""),IF(OR(Q70<=25%,AND(Q70>25%,Q70<=50%, R70=0)),"High Emerging Reader",IF(OR(AND(Q70>25%,Q70<51%, R70>=1),AND(Q70>50%,Q70<76%,R70<=2)),"Developing Reader",IF(OR(AND(Q70>=51%, Q70<76%,R70>=3),AND(Q70>75%,R70<=4)),"Transitioning Reader",IF(AND(Q70>75%,R70>=5),"Reading At Grade Level","")))),"")),"") | Y70: =IF(C70<>"",R70/6,"")
A71: =A70+1 -> 61 | I71: =IF(AND(F71="",G71=""),"",IF(F71<7,F71+G71,F71+10+H71)) | J71: =IF(I71="","",IF(F71<7,IF(I71<=10,"Full Refresher","Moderate Refresher"),IF(I71<27,"Light Refresher","Grade Ready"))) | M71: =IF($C$9<>"",IF(OR(K71=1, K71=2),IF(K71=1,M$7-L71,$P$7-L71),""),"") | P71: =IF(AND(K71>0,M71>0,OR(N71>0,O71>0)),(M71/((N71*60)+O71))*60,"") | Q71: =IFERROR(IF(OR(K71=1, K71=2),IF(K71=1,M71/$M$7,M71/$P$7),""),"") | U71: =IF(J71<>"",IF(J71="Full Refresher","Low Emerging Reader",IF(AND(K71>0,Q71<>""),IF(OR(Q71<=25%,AND(Q71>25%,Q71<=50%, R71=0)),"High Emerging Reader",IF(OR(AND(Q71>25%,Q71<51%, R71>=1),AND(Q71>50%,Q71<76%,R71<=2)),"Developing Reader",IF(OR(AND(Q71>=51%, Q71<76%,R71>=3),AND(Q71>75%,R71<=4)),"Transitioning Reader",IF(AND(Q71>75%,R71>=5),"Reading At Grade Level","")))),"")),"") | Y71: =IF(C71<>"",R71/6,"")
A72: =A71+1 -> 62 | I72: =IF(AND(F72="",G72=""),"",IF(F72<7,F72+G72,F72+10+H72)) | J72: =IF(I72="","",IF(F72<7,IF(I72<=10,"Full Refresher","Moderate Refresher"),IF(I72<27,"Light Refresher","Grade Ready"))) | M72: =IF($C$9<>"",IF(OR(K72=1, K72=2),IF(K72=1,M$7-L72,$P$7-L72),""),"") | P72: =IF(AND(K72>0,M72>0,OR(N72>0,O72>0)),(M72/((N72*60)+O72))*60,"") | Q72: =IFERROR(IF(OR(K72=1, K72=2),IF(K72=1,M72/$M$7,M72/$P$7),""),"") | U72: =IF(J72<>"",IF(J72="Full Refresher","Low Emerging Reader",IF(AND(K72>0,Q72<>""),IF(OR(Q72<=25%,AND(Q72>25%,Q72<=50%, R72=0)),"High Emerging Reader",IF(OR(AND(Q72>25%,Q72<51%, R72>=1),AND(Q72>50%,Q72<76%,R72<=2)),"Developing Reader",IF(OR(AND(Q72>=51%, Q72<76%,R72>=3),AND(Q72>75%,R72<=4)),"Transitioning Reader",IF(AND(Q72>75%,R72>=5),"Reading At Grade Level","")))),"")),"") | Y72: =IF(C72<>"",R72/6,"")
A73: =A72+1 -> 63 | I73: =IF(AND(F73="",G73=""),"",IF(F73<7,F73+G73,F73+10+H73)) | J73: =IF(I73="","",IF(F73<7,IF(I73<=10,"Full Refresher","Moderate Refresher"),IF(I73<27,"Light Refresher","Grade Ready"))) | M73: =IF($C$9<>"",IF(OR(K73=1, K73=2),IF(K73=1,M$7-L73,$P$7-L73),""),"") | P73: =IF(AND(K73>0,M73>0,OR(N73>0,O73>0)),(M73/((N73*60)+O73))*60,"") | Q73: =IFERROR(IF(OR(K73=1, K73=2),IF(K73=1,M73/$M$7,M73/$P$7),""),"") | U73: =IF(J73<>"",IF(J73="Full Refresher","Low Emerging Reader",IF(AND(K73>0,Q73<>""),IF(OR(Q73<=25%,AND(Q73>25%,Q73<=50%, R73=0)),"High Emerging Reader",IF(OR(AND(Q73>25%,Q73<51%, R73>=1),AND(Q73>50%,Q73<76%,R73<=2)),"Developing Reader",IF(OR(AND(Q73>=51%, Q73<76%,R73>=3),AND(Q73>75%,R73<=4)),"Transitioning Reader",IF(AND(Q73>75%,R73>=5),"Reading At Grade Level","")))),"")),"") | Y73: =IF(C73<>"",R73/6,"")
A74: =A73+1 -> 64 | I74: =IF(AND(F74="",G74=""),"",IF(F74<7,F74+G74,F74+10+H74)) | J74: =IF(I74="","",IF(F74<7,IF(I74<=10,"Full Refresher","Moderate Refresher"),IF(I74<27,"Light Refresher","Grade Ready"))) | M74: =IF($C$9<>"",IF(OR(K74=1, K74=2),IF(K74=1,M$7-L74,$P$7-L74),""),"") | P74: =IF(AND(K74>0,M74>0,OR(N74>0,O74>0)),(M74/((N74*60)+O74))*60,"") | Q74: =IFERROR(IF(OR(K74=1, K74=2),IF(K74=1,M74/$M$7,M74/$P$7),""),"") | U74: =IF(J74<>"",IF(J74="Full Refresher","Low Emerging Reader",IF(AND(K74>0,Q74<>""),IF(OR(Q74<=25%,AND(Q74>25%,Q74<=50%, R74=0)),"High Emerging Reader",IF(OR(AND(Q74>25%,Q74<51%, R74>=1),AND(Q74>50%,Q74<76%,R74<=2)),"Developing Reader",IF(OR(AND(Q74>=51%, Q74<76%,R74>=3),AND(Q74>75%,R74<=4)),"Transitioning Reader",IF(AND(Q74>75%,R74>=5),"Reading At Grade Level","")))),"")),"") | Y74: =IF(C74<>"",R74/6,"")
A75: =A74+1 -> 65 | I75: =IF(AND(F75="",G75=""),"",IF(F75<7,F75+G75,F75+10+H75)) | J75: =IF(I75="","",IF(F75<7,IF(I75<=10,"Full Refresher","Moderate Refresher"),IF(I75<27,"Light Refresher","Grade Ready"))) | M75: =IF($C$9<>"",IF(OR(K75=1, K75=2),IF(K75=1,M$7-L75,$P$7-L75),""),"") | P75: =IF(AND(K75>0,M75>0,OR(N75>0,O75>0)),(M75/((N75*60)+O75))*60,"") | Q75: =IFERROR(IF(OR(K75=1, K75=2),IF(K75=1,M75/$M$7,M75/$P$7),""),"") | U75: =IF(J75<>"",IF(J75="Full Refresher","Low Emerging Reader",IF(AND(K75>0,Q75<>""),IF(OR(Q75<=25%,AND(Q75>25%,Q75<=50%, R75=0)),"High Emerging Reader",IF(OR(AND(Q75>25%,Q75<51%, R75>=1),AND(Q75>50%,Q75<76%,R75<=2)),"Developing Reader",IF(OR(AND(Q75>=51%, Q75<76%,R75>=3),AND(Q75>75%,R75<=4)),"Transitioning Reader",IF(AND(Q75>75%,R75>=5),"Reading At Grade Level","")))),"")),"") | Y75: =IF(C75<>"",R75/6,"")
A76: =A75+1 -> 66 | I76: =IF(AND(F76="",G76=""),"",IF(F76<7,F76+G76,F76+10+H76)) | J76: =IF(I76="","",IF(F76<7,IF(I76<=10,"Full Refresher","Moderate Refresher"),IF(I76<27,"Light Refresher","Grade Ready"))) | M76: =IF($C$9<>"",IF(OR(K76=1, K76=2),IF(K76=1,M$7-L76,$P$7-L76),""),"") | P76: =IF(AND(K76>0,M76>0,OR(N76>0,O76>0)),(M76/((N76*60)+O76))*60,"") | Q76: =IFERROR(IF(OR(K76=1, K76=2),IF(K76=1,M76/$M$7,M76/$P$7),""),"") | U76: =IF(J76<>"",IF(J76="Full Refresher","Low Emerging Reader",IF(AND(K76>0,Q76<>""),IF(OR(Q76<=25%,AND(Q76>25%,Q76<=50%, R76=0)),"High Emerging Reader",IF(OR(AND(Q76>25%,Q76<51%, R76>=1),AND(Q76>50%,Q76<76%,R76<=2)),"Developing Reader",IF(OR(AND(Q76>=51%, Q76<76%,R76>=3),AND(Q76>75%,R76<=4)),"Transitioning Reader",IF(AND(Q76>75%,R76>=5),"Reading At Grade Level","")))),"")),"") | Y76: =IF(C76<>"",R76/6,"")
A77: =A76+1 -> 67 | I77: =IF(AND(F77="",G77=""),"",IF(F77<7,F77+G77,F77+10+H77)) | J77: =IF(I77="","",IF(F77<7,IF(I77<=10,"Full Refresher","Moderate Refresher"),IF(I77<27,"Light Refresher","Grade Ready"))) | M77: =IF($C$9<>"",IF(OR(K77=1, K77=2),IF(K77=1,M$7-L77,$P$7-L77),""),"") | P77: =IF(AND(K77>0,M77>0,OR(N77>0,O77>0)),(M77/((N77*60)+O77))*60,"") | Q77: =IFERROR(IF(OR(K77=1, K77=2),IF(K77=1,M77/$M$7,M77/$P$7),""),"") | U77: =IF(J77<>"",IF(J77="Full Refresher","Low Emerging Reader",IF(AND(K77>0,Q77<>""),IF(OR(Q77<=25%,AND(Q77>25%,Q77<=50%, R77=0)),"High Emerging Reader",IF(OR(AND(Q77>25%,Q77<51%, R77>=1),AND(Q77>50%,Q77<76%,R77<=2)),"Developing Reader",IF(OR(AND(Q77>=51%, Q77<76%,R77>=3),AND(Q77>75%,R77<=4)),"Transitioning Reader",IF(AND(Q77>75%,R77>=5),"Reading At Grade Level","")))),"")),"") | Y77: =IF(C77<>"",R77/6,"")
A78: =A77+1 -> 68 | I78: =IF(AND(F78="",G78=""),"",IF(F78<7,F78+G78,F78+10+H78)) | J78: =IF(I78="","",IF(F78<7,IF(I78<=10,"Full Refresher","Moderate Refresher"),IF(I78<27,"Light Refresher","Grade Ready"))) | M78: =IF($C$9<>"",IF(OR(K78=1, K78=2),IF(K78=1,M$7-L78,$P$7-L78),""),"") | P78: =IF(AND(K78>0,M78>0,OR(N78>0,O78>0)),(M78/((N78*60)+O78))*60,"") | Q78: =IFERROR(IF(OR(K78=1, K78=2),IF(K78=1,M78/$M$7,M78/$P$7),""),"") | U78: =IF(J78<>"",IF(J78="Full Refresher","Low Emerging Reader",IF(AND(K78>0,Q78<>""),IF(OR(Q78<=25%,AND(Q78>25%,Q78<=50%, R78=0)),"High Emerging Reader",IF(OR(AND(Q78>25%,Q78<51%, R78>=1),AND(Q78>50%,Q78<76%,R78<=2)),"Developing Reader",IF(OR(AND(Q78>=51%, Q78<76%,R78>=3),AND(Q78>75%,R78<=4)),"Transitioning Reader",IF(AND(Q78>75%,R78>=5),"Reading At Grade Level","")))),"")),"") | Y78: =IF(C78<>"",R78/6,"")
A79: =A78+1 -> 69 | I79: =IF(AND(F79="",G79=""),"",IF(F79<7,F79+G79,F79+10+H79)) | J79: =IF(I79="","",IF(F79<7,IF(I79<=10,"Full Refresher","Moderate Refresher"),IF(I79<27,"Light Refresher","Grade Ready"))) | M79: =IF($C$9<>"",IF(OR(K79=1, K79=2),IF(K79=1,M$7-L79,$P$7-L79),""),"") | P79: =IF(AND(K79>0,M79>0,OR(N79>0,O79>0)),(M79/((N79*60)+O79))*60,"") | Q79: =IFERROR(IF(OR(K79=1, K79=2),IF(K79=1,M79/$M$7,M79/$P$7),""),"") | U79: =IF(J79<>"",IF(J79="Full Refresher","Low Emerging Reader",IF(AND(K79>0,Q79<>""),IF(OR(Q79<=25%,AND(Q79>25%,Q79<=50%, R79=0)),"High Emerging Reader",IF(OR(AND(Q79>25%,Q79<51%, R79>=1),AND(Q79>50%,Q79<76%,R79<=2)),"Developing Reader",IF(OR(AND(Q79>=51%, Q79<76%,R79>=3),AND(Q79>75%,R79<=4)),"Transitioning Reader",IF(AND(Q79>75%,R79>=5),"Reading At Grade Level","")))),"")),"") | Y79: =IF(C79<>"",R79/6,"")
A80: =A79+1 -> 70 | I80: =IF(AND(F80="",G80=""),"",IF(F80<7,F80+G80,F80+10+H80)) | J80: =IF(I80="","",IF(F80<7,IF(I80<=10,"Full Refresher","Moderate Refresher"),IF(I80<27,"Light Refresher","Grade Ready"))) | M80: =IF($C$9<>"",IF(OR(K80=1, K80=2),IF(K80=1,M$7-L80,$P$7-L80),""),"") | P80: =IF(AND(K80>0,M80>0,OR(N80>0,O80>0)),(M80/((N80*60)+O80))*60,"") | Q80: =IFERROR(IF(OR(K80=1, K80=2),IF(K80=1,M80/$M$7,M80/$P$7),""),"") | U80: =IF(J80<>"",IF(J80="Full Refresher","Low Emerging Reader",IF(AND(K80>0,Q80<>""),IF(OR(Q80<=25%,AND(Q80>25%,Q80<=50%, R80=0)),"High Emerging Reader",IF(OR(AND(Q80>25%,Q80<51%, R80>=1),AND(Q80>50%,Q80<76%,R80<=2)),"Developing Reader",IF(OR(AND(Q80>=51%, Q80<76%,R80>=3),AND(Q80>75%,R80<=4)),"Transitioning Reader",IF(AND(Q80>75%,R80>=5),"Reading At Grade Level","")))),"")),"") | Y80: =IF(C80<>"",R80/6,"")
A81: =A80+1 -> 71 | I81: =IF(AND(F81="",G81=""),"",IF(F81<7,F81+G81,F81+10+H81)) | J81: =IF(I81="","",IF(F81<7,IF(I81<=10,"Full Refresher","Moderate Refresher"),IF(I81<27,"Light Refresher","Grade Ready"))) | M81: =IF($C$9<>"",IF(OR(K81=1, K81=2),IF(K81=1,M$7-L81,$P$7-L81),""),"") | P81: =IF(AND(K81>0,M81>0,OR(N81>0,O81>0)),(M81/((N81*60)+O81))*60,"") | Q81: =IFERROR(IF(OR(K81=1, K81=2),IF(K81=1,M81/$M$7,M81/$P$7),""),"") | U81: =IF(J81<>"",IF(J81="Full Refresher","Low Emerging Reader",IF(AND(K81>0,Q81<>""),IF(OR(Q81<=25%,AND(Q81>25%,Q81<=50%, R81=0)),"High Emerging Reader",IF(OR(AND(Q81>25%,Q81<51%, R81>=1),AND(Q81>50%,Q81<76%,R81<=2)),"Developing Reader",IF(OR(AND(Q81>=51%, Q81<76%,R81>=3),AND(Q81>75%,R81<=4)),"Transitioning Reader",IF(AND(Q81>75%,R81>=5),"Reading At Grade Level","")))),"")),"") | Y81: =IF(C81<>"",R81/6,"")
... A109: =A108+1 -> 99 | I109: =IF(AND(F109="",G109=""),"",IF(F109<7,F109+G109,F109+10+H109)) | J109: =IF(I109="","",IF(F109<7,IF(I109<=10,"Full Refresher","Moderate Refresher"),IF(I109<27,"Light Refresher","Grade Ready"))) | M109: =IF($C$9<>"",IF(OR(K109=1, K109=2),IF(K109=1,M$7-L109,$P$7-L109),""),"") | P109: =IF(AND(K109>0,M109>0,OR(N109>0,O109>0)),(M109/((N109*60)+O109))*60,"") | Q109: =IFERROR(IF(OR(K109=1, K109=2),IF(K109=1,M109/$M$7,M109/$P$7),""),"") | U109: =IF(J109<>"",IF(J109="Full Refresher","Low Emerging Reader",IF(AND(K109>0,Q109<>""),IF(OR(Q109<=25%,AND(Q109>25%,Q109<=50%, R109=0)),"High Emerging Reader",IF(OR(AND(Q109>25%,Q109<51%, R109>=1),AND(Q109>50%,Q109<76%,R109<=2)),"Developing Reader",IF(OR(AND(Q109>=51%, Q109<76%,R109>=3),AND(Q109>75%,R109<=4)),"Transitioning Reader",IF(AND(Q109>75%,R109>=5),"Reading At Grade Level","")))),"")),"") | Y109: =IF(C109<>"",R109/6,"")
A110: 100 | I110: =IF(AND(F110="",G110=""),"",IF(F110<7,F110+G110,F110+10+H110)) | J110: =IF(I110="","",IF(F110<7,IF(I110<=10,"Full Refresher","Moderate Refresher"),IF(I110<27,"Light Refresher","Grade Ready"))) | M110: =IF($C$9<>"",IF(OR(K110=1, K110=2),IF(K110=1,M$7-L110,$P$7-L110),""),"") | P110: =IF(AND(K110>0,M110>0,OR(N110>0,O110>0)),(M110/((N110*60)+O110))*60,"") | Q110: =IFERROR(IF(OR(K110=1, K110=2),IF(K110=1,M110/$M$7,M110/$P$7),""),"") | U110: =IF(J110<>"",IF(J110="Full Refresher","Low Emerging Reader",IF(AND(K110>0,Q110<>""),IF(OR(Q110<=25%,AND(Q110>25%,Q110<=50%, R110=0)),"High Emerging Reader",IF(OR(AND(Q110>25%,Q110<51%, R110>=1),AND(Q110>50%,Q110<76%,R110<=2)),"Developing Reader",IF(OR(AND(Q110>=51%, Q110<76%,R110>=3),AND(Q110>75%,R110<=4)),"Transitioning Reader",IF(AND(Q110>75%,R110>=5),"Reading At Grade Level","")))),"")),"") | Y110: =IF(C110<>"",R110/6,"")

Sheet G2 FIL Reading Scoresheet
A1: CRLA2v1
A3: ASSESSMENT TYPE | C3: ='G2 MT Reading Scoresheet'!$C$3 -> 0
A4: School ID: | C4: ='G2 MT Reading Scoresheet'!C4 -> 0 | D4: Total Enrolment | F4: =D6+E6 -> 0 | G4: Total Assessed : | I4: =COUNTIF(F11:F110,"<>") -> 100
A5: Schoo Name: | C5: ='G2 MT Reading Scoresheet'!C5 -> 0 | D5: Male | E5: Female | F5: Assessment Part 1 (Word Recognition and Sentences Reading) | J5: WORDS SCORE 0 to 10 – Full Refresher 11 to 16 – Moderate Refresher SENTENCE SCORE 17 to 26 – Light Refresher 27 to 30 – Grade Ready | K5: Assessment Part 2 (Reading Fluency and Comprehension)
A6: Teacher: | C6: ='G2 MT Reading Scoresheet'!C6 -> 0 | D6: ='G2 MT Reading Scoresheet'!D6 -> 0 | E6: ='G2 MT Reading Scoresheet'!E6 -> 0
A7: Grade: | C7: ='G2 MT Reading Scoresheet'!C7 -> Grade 2 | D7: Total Words per Story | F7: Task 1 – Write the number of Words sounded out correctly | G7: Rhymes (Task 2) If task 1 score is 0 to 6 | H7: Sentence (Task 2) If task 1 score is 7 to 10 Task 2L=10 | I7: Total Score = Task 1 Score + Task 2L+Task 2H Score | K7: Total Words Per Story | L7: Story 1 | M7: =_xlfn.IFNA(IF(X9=1,Y9,D9),"") -> 96 | N7: Story 2 | P7: =_xlfn.IFNA(IF(X9=1,Z9,E9),"") -> 95
A8: Section: | C8: ='G2 MT Reading Scoresheet'!C8 -> 0 | D8: Story 1 | E8: Story 2 | K8: Story Number 1 or 2 | L8: Total Reading Miscues | M8: Number of words read within 2 mins | N8: Total Time Used in Reading (Max : 2 Mins) | P8: Number of Words per Minute (WPM)
A9: Language: | C9: Filipino | X9: =IF(_xlfn.IFNA(VLOOKUP($C$9,List!$G$2:$M$20,1,0),"")=C9,1,0) -> 1 | Y9: =VLOOKUP($C$9,List!$G$2:$M$20,4,0) -> 96 | Z9: =VLOOKUP($C$9,List!$G$2:$M$20,7,0) -> 95
A10: S/N | B10: LRN | C10: Name of Learner | D10: Sex | E10: Date of Asessment | F10: Task 1 (10) | G10: Words (10) | H10: Sentences (10) | I10: Total Score | J10: Part 1 Reading Level | K10: Story Number | L10: Number of Miscue | M10: Words Read | N10: Total Mins Secs | P10: WPM | Q10: % of Correct Words Read | R10: Total Correct Answer | S10: Leaner Experience (Rating 1-5) | T10: Observation Level | U10: READING PROFILE | V10: Remarks
A11: 1 | B11: =IF('G2 MT Reading Scoresheet'!B11<>"",'G2 MT Reading Scoresheet'!B11,"") | C11: =IF('G2 MT Reading Scoresheet'!C11<>"",'G2 MT Reading Scoresheet'!C11,"") | D11: =IF('G2 MT Reading Scoresheet'!D11<>"",'G2 MT Reading Scoresheet'!D11,"") | E11: =IF('G2 MT Reading Scoresheet'!E11<>"",'G2 MT Reading Scoresheet'!E11,"") | F11: =IF('G2 MT Reading Scoresheet'!F11<>"",'G2 MT Reading Scoresheet'!F11,"") | G11: =IF('G2 MT Reading Scoresheet'!G11<>"",'G2 MT Reading Scoresheet'!G11,"") | H11: =IF('G2 MT Reading Scoresheet'!H11<>"",'G2 MT Reading Scoresheet'!H11,"") | I11: =IF('G2 MT Reading Scoresheet'!I11<>"",'G2 MT Reading Scoresheet'!I11,"") | ... U11: =IF('G2 MT Reading Scoresheet'!U11<>"",'G2 MT Reading Scoresheet'!U11,"") | Y11: =IF(C11<>"",R11/6,"")
A12: 2 | B12: =IF('G2 MT Reading Scoresheet'!B12<>"",'G2 MT Reading Scoresheet'!B12,"") | C12: =IF('G2 MT Reading Scoresheet'!C12<>"",'G2 MT Reading Scoresheet'!C12,"") | D12: =IF('G2 MT Reading Scoresheet'!D12<>"",'G2 MT Reading Scoresheet'!D12,"") | E12: =IF('G2 MT Reading Scoresheet'!E12<>"",'G2 MT Reading Scoresheet'!E12,"") | F12: =IF('G2 MT Reading Scoresheet'!F12<>"",'G2 MT Reading Scoresheet'!F12,"") | G12: =IF('G2 MT Reading Scoresheet'!G12<>"",'G2 MT Reading Scoresheet'!G12,"") | H12: =IF('G2 MT Reading Scoresheet'!H12<>"",'G2 MT Reading Scoresheet'!H12,"") | I12: =IF('G2 MT Reading Scoresheet'!I12<>"",'G2 MT Reading Scoresheet'!I12,"") | ... U12: =IF('G2 MT Reading Scoresheet'!U12<>"",'G2 MT Reading Scoresheet'!U12,"") | Y12: =IF(C12<>"",R12/6,"")
A13: 3 | B13: =IF('G2 MT Reading Scoresheet'!B13<>"",'G2 MT Reading Scoresheet'!B13,"") | C13: =IF('G2 MT Reading Scoresheet'!C13<>"",'G2 MT Reading Scoresheet'!C13,"") | D13: =IF('G2 MT Reading Scoresheet'!D13<>"",'G2 MT Reading Scoresheet'!D13,"") | E13: =IF('G2 MT Reading Scoresheet'!E13<>"",'G2 MT Reading Scoresheet'!E13,"") | F13: =IF('G2 MT Reading Scoresheet'!F13<>"",'G2 MT Reading Scoresheet'!F13,"") | G13: =IF('G2 MT Reading Scoresheet'!G13<>"",'G2 MT Reading Scoresheet'!G13,"") | H13: =IF('G2 MT Reading Scoresheet'!H13<>"",'G2 MT Reading Scoresheet'!H13,"") | I13: =IF('G2 MT Reading Scoresheet'!I13<>"",'G2 MT Reading Scoresheet'!I13,"") | ... U13: =IF('G2 MT Reading Scoresheet'!U13<>"",'G2 MT Reading Scoresheet'!U13,"") | Y13: =IF(C13<>"",R13/6,"")
A14: 4 | B14: =IF('G2 MT Reading Scoresheet'!B14<>"",'G2 MT Reading Scoresheet'!B14,"") | C14: =IF('G2 MT Reading Scoresheet'!C14<>"",'G2 MT Reading Scoresheet'!C14,"") | D14: =IF('G2 MT Reading Scoresheet'!D14<>"",'G2 MT Reading Scoresheet'!D14,"") | E14: =IF('G2 MT Reading Scoresheet'!E14<>"",'G2 MT Reading Scoresheet'!E14,"") | F14: =IF('G2 MT Reading Scoresheet'!F14<>"",'G2 MT Reading Scoresheet'!F14,"") | G14: =IF('G2 MT Reading Scoresheet'!G14<>"",'G2 MT Reading Scoresheet'!G14,"") | H14: =IF('G2 MT Reading Scoresheet'!H14<>"",'G2 MT Reading Scoresheet'!H14,"") | I14: =IF('G2 MT Reading Scoresheet'!I14<>"",'G2 MT Reading Scoresheet'!I14,"") | ... U14: =IF('G2 MT Reading Scoresheet'!U14<>"",'G2 MT Reading Scoresheet'!U14,"") | Y14: =IF(C14<>"",R14/6,"")
A15: 5 | B15: =IF('G2 MT Reading Scoresheet'!B15<>"",'G2 MT Reading Scoresheet'!B15,"") | C15: =IF('G2 MT Reading Scoresheet'!C15<>"",'G2 MT Reading Scoresheet'!C15,"") | D15: =IF('G2 MT Reading Scoresheet'!D15<>"",'G2 MT Reading Scoresheet'!D15,"") | E15: =IF('G2 MT Reading Scoresheet'!E15<>"",'G2 MT Reading Scoresheet'!E15,"") | F15: =IF('G2 MT Reading Scoresheet'!F15<>"",'G2 MT Reading Scoresheet'!F15,"") | G15: =IF('G2 MT Reading Scoresheet'!G15<>"",'G2 MT Reading Scoresheet'!G15,"") | H15: =IF('G2 MT Reading Scoresheet'!H15<>"",'G2 MT Reading Scoresheet'!H15,"") | I15: =IF('G2 MT Reading Scoresheet'!I15<>"",'G2 MT Reading Scoresheet'!I15,"") | ... U15: =IF('G2 MT Reading Scoresheet'!U15<>"",'G2 MT Reading Scoresheet'!U15,"") | Y15: =IF(C15<>"",R15/6,"")
A16: 6 | B16: =IF('G2 MT Reading Scoresheet'!B16<>"",'G2 MT Reading Scoresheet'!B16,"") | C16: =IF('G2 MT Reading Scoresheet'!C16<>"",'G2 MT Reading Scoresheet'!C16,"") | D16: =IF('G2 MT Reading Scoresheet'!D16<>"",'G2 MT Reading Scoresheet'!D16,"") | E16: =IF('G2 MT Reading Scoresheet'!E16<>"",'G2 MT Reading Scoresheet'!E16,"") | F16: =IF('G2 MT Reading Scoresheet'!F16<>"",'G2 MT Reading Scoresheet'!F16,"") | G16: =IF('G2 MT Reading Scoresheet'!G16<>"",'G2 MT Reading Scoresheet'!G16,"") | H16: =IF('G2 MT Reading Scoresheet'!H16<>"",'G2 MT Reading Scoresheet'!H16,"") | I16: =IF('G2 MT Reading Scoresheet'!I16<>"",'G2 MT Reading Scoresheet'!I16,"") | ... U16: =IF('G2 MT Reading Scoresheet'!U16<>"",'G2 MT Reading Scoresheet'!U16,"") | Y16: =IF(C16<>"",R16/6,"")
A17: 7 | B17: =IF('G2 MT Reading Scoresheet'!B17<>"",'G2 MT Reading Scoresheet'!B17,"") | C17: =IF('G2 MT Reading Scoresheet'!C17<>"",'G2 MT Reading Scoresheet'!C17,"") | D17: =IF('G2 MT Reading Scoresheet'!D17<>"",'G2 MT Reading Scoresheet'!D17,"") | E17: =IF('G2 MT Reading Scoresheet'!E17<>"",'G2 MT Reading Scoresheet'!E17,"") | F17: =IF('G2 MT Reading Scoresheet'!F17<>"",'G2 MT Reading Scoresheet'!F17,"") | G17: =IF('G2 MT Reading Scoresheet'!G17<>"",'G2 MT Reading Scoresheet'!G17,"") | H17: =IF('G2 MT Reading Scoresheet'!H17<>"",'G2 MT Reading Scoresheet'!H17,"") | I17: =IF('G2 MT Reading Scoresheet'!I17<>"",'G2 MT Reading Scoresheet'!I17,"") | ... U17: =IF('G2 MT Reading Scoresheet'!U17<>"",'G2 MT Reading Scoresheet'!U17,"") | Y17: =IF(C17<>"",R17/6,"")
A18: 8 | B18: =IF('G2 MT Reading Scoresheet'!B18<>"",'G2 MT Reading Scoresheet'!B18,"") | C18: =IF('G2 MT Reading Scoresheet'!C18<>"",'G2 MT Reading Scoresheet'!C18,"") | D18: =IF('G2 MT Reading Scoresheet'!D18<>"",'G2 MT Reading Scoresheet'!D18,"") | E18: =IF('G2 MT Reading Scoresheet'!E18<>"",'G2 MT Reading Scoresheet'!E18,"") | F18: =IF('G2 MT Reading Scoresheet'!F18<>"",'G2 MT Reading Scoresheet'!F18,"") | G18: =IF('G2 MT Reading Scoresheet'!G18<>"",'G2 MT Reading Scoresheet'!G18,"") | H18: =IF('G2 MT Reading Scoresheet'!H18<>"",'G2 MT Reading Scoresheet'!H18,"") | I18: =IF('G2 MT Reading Scoresheet'!I18<>"",'G2 MT Reading Scoresheet'!I18,"") | ... U18: =IF('G2 MT Reading Scoresheet'!U18<>"",'G2 MT Reading Scoresheet'!U18,"") | Y18: =IF(C18<>"",R18/6,"")
A19: 9 | B19: =IF('G2 MT Reading Scoresheet'!B19<>"",'G2 MT Reading Scoresheet'!B19,"") | C19: =IF('G2 MT Reading Scoresheet'!C19<>"",'G2 MT Reading Scoresheet'!C19,"") | D19: =IF('G2 MT Reading Scoresheet'!D19<>"",'G2 MT Reading Scoresheet'!D19,"") | E19: =IF('G2 MT Reading Scoresheet'!E19<>"",'G2 MT Reading Scoresheet'!E19,"") | F19: =IF('G2 MT Reading Scoresheet'!F19<>"",'G2 MT Reading Scoresheet'!F19,"") | G19: =IF('G2 MT Reading Scoresheet'!G19<>"",'G2 MT Reading Scoresheet'!G19,"") | H19: =IF('G2 MT Reading Scoresheet'!H19<>"",'G2 MT Reading Scoresheet'!H19,"") | I19: =IF('G2 MT Reading Scoresheet'!I19<>"",'G2 MT Reading Scoresheet'!I19,"") | ... U19: =IF('G2 MT Reading Scoresheet'!U19<>"",'G2 MT Reading Scoresheet'!U19,"") | Y19: =IF(C19<>"",R19/6,"")
A20: 10 | B20: =IF('G2 MT Reading Scoresheet'!B20<>"",'G2 MT Reading Scoresheet'!B20,"") | C20: =IF('G2 MT Reading Scoresheet'!C20<>"",'G2 MT Reading Scoresheet'!C20,"") | D20: =IF('G2 MT Reading Scoresheet'!D20<>"",'G2 MT Reading Scoresheet'!D20,"") | E20: =IF('G2 MT Reading Scoresheet'!E20<>"",'G2 MT Reading Scoresheet'!E20,"") | F20: =IF('G2 MT Reading Scoresheet'!F20<>"",'G2 MT Reading Scoresheet'!F20,"") | G20: =IF('G2 MT Reading Scoresheet'!G20<>"",'G2 MT Reading Scoresheet'!G20,"") | H20: =IF('G2 MT Reading Scoresheet'!H20<>"",'G2 MT Reading Scoresheet'!H20,"") | I20: =IF('G2 MT Reading Scoresheet'!I20<>"",'G2 MT Reading Scoresheet'!I20,"") | ... U20: =IF('G2 MT Reading Scoresheet'!U20<>"",'G2 MT Reading Scoresheet'!U20,"") | Y20: =IF(C20<>"",R20/6,"")
A21: 11 | B21: =IF('G2 MT Reading Scoresheet'!B21<>"",'G2 MT Reading Scoresheet'!B21,"") | C21: =IF('G2 MT Reading Scoresheet'!C21<>"",'G2 MT Reading Scoresheet'!C21,"") | D21: =IF('G2 MT Reading Scoresheet'!D21<>"",'G2 MT Reading Scoresheet'!D21,"") | E21: =IF('G2 MT Reading Scoresheet'!E21<>"",'G2 MT Reading Scoresheet'!E21,"") | F21: =IF('G2 MT Reading Scoresheet'!F21<>"",'G2 MT Reading Scoresheet'!F21,"") | G21: =IF('G2 MT Reading Scoresheet'!G21<>"",'G2 MT Reading Scoresheet'!G21,"") | H21: =IF('G2 MT Reading Scoresheet'!H21<>"",'G2 MT Reading Scoresheet'!H21,"") | I21: =IF('G2 MT Reading Scoresheet'!I21<>"",'G2 MT Reading Scoresheet'!I21,"") | ... U21: =IF('G2 MT Reading Scoresheet'!U21<>"",'G2 MT Reading Scoresheet'!U21,"") | Y21: =IF(C21<>"",R21/6,"")
A22: 12 | B22: =IF('G2 MT Reading Scoresheet'!B22<>"",'G2 MT Reading Scoresheet'!B22,"") | C22: =IF('G2 MT Reading Scoresheet'!C22<>"",'G2 MT Reading Scoresheet'!C22,"") | D22: =IF('G2 MT Reading Scoresheet'!D22<>"",'G2 MT Reading Scoresheet'!D22,"") | E22: =IF('G2 MT Reading Scoresheet'!E22<>"",'G2 MT Reading Scoresheet'!E22,"") | F22: =IF('G2 MT Reading Scoresheet'!F22<>"",'G2 MT Reading Scoresheet'!F22,"") | G22: =IF('G2 MT Reading Scoresheet'!G22<>"",'G2 MT Reading Scoresheet'!G22,"") | H22: =IF('G2 MT Reading Scoresheet'!H22<>"",'G2 MT Reading Scoresheet'!H22,"") | I22: =IF('G2 MT Reading Scoresheet'!I22<>"",'G2 MT Reading Scoresheet'!I22,"") | ... U22: =IF('G2 MT Reading Scoresheet'!U22<>"",'G2 MT Reading Scoresheet'!U22,"") | Y22: =IF(C22<>"",R22/6,"")
... A69: 59 | B69: =IF('G2 MT Reading Scoresheet'!B69<>"",'G2 MT Reading Scoresheet'!B69,"") | C69: =IF('G2 MT Reading Scoresheet'!C69<>"",'G2 MT Reading Scoresheet'!C69,"") | D69: =IF('G2 MT Reading Scoresheet'!D69<>"",'G2 MT Reading Scoresheet'!D69,"") | E69: =IF('G2 MT Reading Scoresheet'!E69<>"",'G2 MT Reading Scoresheet'!E69,"") | F69: =IF('G2 MT Reading Scoresheet'!F69<>"",'G2 MT Reading Scoresheet'!F69,"") | G69: =IF('G2 MT Reading Scoresheet'!G69<>"",'G2 MT Reading Scoresheet'!G69,"") | H69: =IF('G2 MT Reading Scoresheet'!H69<>"",'G2 MT Reading Scoresheet'!H69,"") | I69: =IF('G2 MT Reading Scoresheet'!I69<>"",'G2 MT Reading Scoresheet'!I69,"") | ... U69: =IF('G2 MT Reading Scoresheet'!U69<>"",'G2 MT Reading Scoresheet'!U69,"") | Y69: =IF(C69<>"",R69/6,"")
A70: =A69+1 -> 60 | B70: =IF('G2 MT Reading Scoresheet'!B70<>"",'G2 MT Reading Scoresheet'!B70,"") | C70: =IF('G2 MT Reading Scoresheet'!C70<>"",'G2 MT Reading Scoresheet'!C70,"") | D70: =IF('G2 MT Reading Scoresheet'!D70<>"",'G2 MT Reading Scoresheet'!D70,"") | E70: =IF('G2 MT Reading Scoresheet'!E70<>"",'G2 MT Reading Scoresheet'!E70,"") | F70: =IF('G2 MT Reading Scoresheet'!F70<>"",'G2 MT Reading Scoresheet'!F70,"") | G70: =IF('G2 MT Reading Scoresheet'!G70<>"",'G2 MT Reading Scoresheet'!G70,"") | H70: =IF('G2 MT Reading Scoresheet'!H70<>"",'G2 MT Reading Scoresheet'!H70,"") | I70: =IF('G2 MT Reading Scoresheet'!I70<>"",'G2 MT Reading Scoresheet'!I70,"") | ... U70: =IF('G2 MT Reading Scoresheet'!U70<>"",'G2 MT Reading Scoresheet'!U70,"") | Y70: =IF(C70<>"",R70/6,"")
A71: =A70+1 -> 61 | B71: =IF('G2 MT Reading Scoresheet'!B71<>"",'G2 MT Reading Scoresheet'!B71,"") | C71: =IF('G2 MT Reading Scoresheet'!C71<>"",'G2 MT Reading Scoresheet'!C71,"") | D71: =IF('G2 MT Reading Scoresheet'!D71<>"",'G2 MT Reading Scoresheet'!D71,"") | E71: =IF('G2 MT Reading Scoresheet'!E71<>"",'G2 MT Reading Scoresheet'!E71,"") | F71: =IF('G2 MT Reading Scoresheet'!F71<>"",'G2 MT Reading Scoresheet'!F71,"") | G71: =IF('G2 MT Reading Scoresheet'!G71<>"",'G2 MT Reading Scoresheet'!G71,"") | H71: =IF('G2 MT Reading Scoresheet'!H71<>"",'G2 MT Reading Scoresheet'!H71,"") | I71: =IF('G2 MT Reading Scoresheet'!I71<>"",'G2 MT Reading Scoresheet'!I71,"") | ... U71: =IF('G2 MT Reading Scoresheet'!U71<>"",'G2 MT Reading Scoresheet'!U71,"") | Y71: =IF(C71<>"",R71/6,"")
A72: =A71+1 -> 62 | B72: =IF('G2 MT Reading Scoresheet'!B72<>"",'G2 MT Reading Scoresheet'!B72,"") | C72: =IF('G2 MT Reading Scoresheet'!C72<>"",'G2 MT Reading Scoresheet'!C72,"") | D72: =IF('G2 MT Reading Scoresheet'!D72<>"",'G2 MT Reading Scoresheet'!D72,"") | E72: =IF('G2 MT Reading Scoresheet'!E72<>"",'G2 MT Reading Scoresheet'!E72,"") | F72: =IF('G2 MT Reading Scoresheet'!F72<>"",'G2 MT Reading Scoresheet'!F72,"") | G72: =IF('G2 MT Reading Scoresheet'!G72<>"",'G2 MT Reading Scoresheet'!G72,"") | H72: =IF('G2 MT Reading Scoresheet'!H72<>"",'G2 MT Reading Scoresheet'!H72,"") | I72: =IF('G2 MT Reading Scoresheet'!I72<>"",'G2 MT Reading Scoresheet'!I72,"") | ... U72: =IF('G2 MT Reading Scoresheet'!U72<>"",'G2 MT Reading Scoresheet'!U72,"") | Y72: =IF(C72<>"",R72/6,"")
A73: =A72+1 -> 63 | B73: =IF('G2 MT Reading Scoresheet'!B73<>"",'G2 MT Reading Scoresheet'!B73,"") | C73: =IF('G2 MT Reading Scoresheet'!C73<>"",'G2 MT Reading Scoresheet'!C73,"") | D73: =IF('G2 MT Reading Scoresheet'!D73<>"",'G2 MT Reading Scoresheet'!D73,"") | E73: =IF('G2 MT Reading Scoresheet'!E73<>"",'G2 MT Reading Scoresheet'!E73,"") | F73: =IF('G2 MT Reading Scoresheet'!F73<>"",'G2 MT Reading Scoresheet'!F73,"") | G73: =IF('G2 MT Reading Scoresheet'!G73<>"",'G2 MT Reading Scoresheet'!G73,"") | H73: =IF('G2 MT Reading Scoresheet'!H73<>"",'G2 MT Reading Scoresheet'!H73,"") | I73: =IF('G2 MT Reading Scoresheet'!I73<>"",'G2 MT Reading Scoresheet'!I73,"") | ... U73: =IF('G2 MT Reading Scoresheet'!U73<>"",'G2 MT Reading Scoresheet'!U73,"") | Y73: =IF(C73<>"",R73/6,"")
A74: =A73+1 -> 64 | B74: =IF('G2 MT Reading Scoresheet'!B74<>"",'G2 MT Reading Scoresheet'!B74,"") | C74: =IF('G2 MT Reading Scoresheet'!C74<>"",'G2 MT Reading Scoresheet'!C74,"") | D74: =IF('G2 MT Reading Scoresheet'!D74<>"",'G2 MT Reading Scoresheet'!D74,"") | E74: =IF('G2 MT Reading Scoresheet'!E74<>"",'G2 MT Reading Scoresheet'!E74,"") | F74: =IF('G2 MT Reading Scoresheet'!F74<>"",'G2 MT Reading Scoresheet'!F74,"") | G74: =IF('G2 MT Reading Scoresheet'!G74<>"",'G2 MT Reading Scoresheet'!G74,"") | H74: =IF('G2 MT Reading Scoresheet'!H74<>"",'G2 MT Reading Scoresheet'!H74,"") | I74: =IF('G2 MT Reading Scoresheet'!I74<>"",'G2 MT Reading Scoresheet'!I74,"") | ... U74: =IF('G2 MT Reading Scoresheet'!U74<>"",'G2 MT Reading Scoresheet'!U74,"") | Y74: =IF(C74<>"",R74/6,"")
A75: =A74+1 -> 65 | B75: =IF('G2 MT Reading Scoresheet'!B75<>"",'G2 MT Reading Scoresheet'!B75,"") | C75: =IF('G2 MT Reading Scoresheet'!C75<>"",'G2 MT Reading Scoresheet'!C75,"") | D75: =IF('G2 MT Reading Scoresheet'!D75<>"",'G2 MT Reading Scoresheet'!D75,"") | E75: =IF('G2 MT Reading Scoresheet'!E75<>"",'G2 MT Reading Scoresheet'!E75,"") | F75: =IF('G2 MT Reading Scoresheet'!F75<>"",'G2 MT Reading Scoresheet'!F75,"") | G75: =IF('G2 MT Reading Scoresheet'!G75<>"",'G2 MT Reading Scoresheet'!G75,"") | H75: =IF('G2 MT Reading Scoresheet'!H75<>"",'G2 MT Reading Scoresheet'!H75,"") | I75: =IF('G2 MT Reading Scoresheet'!I75<>"",'G2 MT Reading Scoresheet'!I75,"") | ... U75: =IF('G2 MT Reading Scoresheet'!U75<>"",'G2 MT Reading Scoresheet'!U75,"") | Y75: =IF(C75<>"",R75/6,"")
A76: =A75+1 -> 66 | B76: =IF('G2 MT Reading Scoresheet'!B76<>"",'G2 MT Reading Scoresheet'!B76,"") | C76: =IF('G2 MT Reading Scoresheet'!C76<>"",'G2 MT Reading Scoresheet'!C76,"") | D76: =IF('G2 MT Reading Scoresheet'!D76<>"",'G2 MT Reading Scoresheet'!D76,"") | E76: =IF('G2 MT Reading Scoresheet'!E76<>"",'G2 MT Reading Scoresheet'!E76,"") | F76: =IF('G2 MT Reading Scoresheet'!F76<>"",'G2 MT Reading Scoresheet'!F76,"") | G76: =IF('G2 MT Reading Scoresheet'!G76<>"",'G2 MT Reading Scoresheet'!G76,"") | H76: =IF('G2 MT Reading Scoresheet'!H76<>"",'G2 MT Reading Scoresheet'!H76,"") | I76: =IF('G2 MT Reading Scoresheet'!I76<>"",'G2 MT Reading Scoresheet'!I76,"") | ... U76: =IF('G2 MT Reading Scoresheet'!U76<>"",'G2 MT Reading Scoresheet'!U76,"") | Y76: =IF(C76<>"",R76/6,"")
A77: =A76+1 -> 67 | B77: =IF('G2 MT Reading Scoresheet'!B77<>"",'G2 MT Reading Scoresheet'!B77,"") | C77: =IF('G2 MT Reading Scoresheet'!C77<>"",'G2 MT Reading Scoresheet'!C77,"") | D77: =IF('G2 MT Reading Scoresheet'!D77<>"",'G2 MT Reading Scoresheet'!D77,"") | E77: =IF('G2 MT Reading Scoresheet'!E77<>"",'G2 MT Reading Scoresheet'!E77,"") | F77: =IF('G2 MT Reading Scoresheet'!F77<>"",'G2 MT Reading Scoresheet'!F77,"") | G77: =IF('G2 MT Reading Scoresheet'!G77<>"",'G2 MT Reading Scoresheet'!G77,"") | H77: =IF('G2 MT Reading Scoresheet'!H77<>"",'G2 MT Reading Scoresheet'!H77,"") | I77: =IF('G2 MT Reading Scoresheet'!I77<>"",'G2 MT Reading Scoresheet'!I77,"") | ... U77: =IF('G2 MT Reading Scoresheet'!U77<>"",'G2 MT Reading Scoresheet'!U77,"") | Y77: =IF(C77<>"",R77/6,"")
A78: =A77+1 -> 68 | B78: =IF('G2 MT Reading Scoresheet'!B78<>"",'G2 MT Reading Scoresheet'!B78,"") | C78: =IF('G2 MT Reading Scoresheet'!C78<>"",'G2 MT Reading Scoresheet'!C78,"") | D78: =IF('G2 MT Reading Scoresheet'!D78<>"",'G2 MT Reading Scoresheet'!D78,"") | E78: =IF('G2 MT Reading Scoresheet'!E78<>"",'G2 MT Reading Scoresheet'!E78,"") | F78: =IF('G2 MT Reading Scoresheet'!F78<>"",'G2 MT Reading Scoresheet'!F78,"") | G78: =IF('G2 MT Reading Scoresheet'!G78<>"",'G2 MT Reading Scoresheet'!G78,"") | H78: =IF('G2 MT Reading Scoresheet'!H78<>"",'G2 MT Reading Scoresheet'!H78,"") | I78: =IF('G2 MT Reading Scoresheet'!I78<>"",'G2 MT Reading Scoresheet'!I78,"") | ... U78: =IF('G2 MT Reading Scoresheet'!U78<>"",'G2 MT Reading Scoresheet'!U78,"") | Y78: =IF(C78<>"",R78/6,"")
A79: =A78+1 -> 69 | B79: =IF('G2 MT Reading Scoresheet'!B79<>"",'G2 MT Reading Scoresheet'!B79,"") | C79: =IF('G2 MT Reading Scoresheet'!C79<>"",'G2 MT Reading Scoresheet'!C79,"") | D79: =IF('G2 MT Reading Scoresheet'!D79<>"",'G2 MT Reading Scoresheet'!D79,"") | E79: =IF('G2 MT Reading Scoresheet'!E79<>"",'G2 MT Reading Scoresheet'!E79,"") | F79: =IF('G2 MT Reading Scoresheet'!F79<>"",'G2 MT Reading Scoresheet'!F79,"") | G79: =IF('G2 MT Reading Scoresheet'!G79<>"",'G2 MT Reading Scoresheet'!G79,"") | H79: =IF('G2 MT Reading Scoresheet'!H79<>"",'G2 MT Reading Scoresheet'!H79,"") | I79: =IF('G2 MT Reading Scoresheet'!I79<>"",'G2 MT Reading Scoresheet'!I79,"") | ... U79: =IF('G2 MT Reading Scoresheet'!U79<>"",'G2 MT Reading Scoresheet'!U79,"") | Y79: =IF(C79<>"",R79/6,"")
A80: =A79+1 -> 70 | B80: =IF('G2 MT Reading Scoresheet'!B80<>"",'G2 MT Reading Scoresheet'!B80,"") | C80: =IF('G2 MT Reading Scoresheet'!C80<>"",'G2 MT Reading Scoresheet'!C80,"") | D80: =IF('G2 MT Reading Scoresheet'!D80<>"",'G2 MT Reading Scoresheet'!D80,"") | E80: =IF('G2 MT Reading Scoresheet'!E80<>"",'G2 MT Reading Scoresheet'!E80,"") | F80: =IF('G2 MT Reading Scoresheet'!F80<>"",'G2 MT Reading Scoresheet'!F80,"") | G80: =IF('G2 MT Reading Scoresheet'!G80<>"",'G2 MT Reading Scoresheet'!G80,"") | H80: =IF('G2 MT Reading Scoresheet'!H80<>"",'G2 MT Reading Scoresheet'!H80,"") | I80: =IF('G2 MT Reading Scoresheet'!I80<>"",'G2 MT Reading Scoresheet'!I80,"") | ... U80: =IF('G2 MT Reading Scoresheet'!U80<>"",'G2 MT Reading Scoresheet'!U80,"") | Y80: =IF(C80<>"",R80/6,"")
A81: =A80+1 -> 71 | B81: =IF('G2 MT Reading Scoresheet'!B81<>"",'G2 MT Reading Scoresheet'!B81,"") | C81: =IF('G2 MT Reading Scoresheet'!C81<>"",'G2 MT Reading Scoresheet'!C81,"") | D81: =IF('G2 MT Reading Scoresheet'!D81<>"",'G2 MT Reading Scoresheet'!D81,"") | E81: =IF('G2 MT Reading Scoresheet'!E81<>"",'G2 MT Reading Scoresheet'!E81,"") | F81: =IF('G2 MT Reading Scoresheet'!F81<>"",'G2 MT Reading Scoresheet'!F81,"") | G81: =IF('G2 MT Reading Scoresheet'!G81<>"",'G2 MT Reading Scoresheet'!G81,"") | H81: =IF('G2 MT Reading Scoresheet'!H81<>"",'G2 MT Reading Scoresheet'!H81,"") | I81: =IF('G2 MT Reading Scoresheet'!I81<>"",'G2 MT Reading Scoresheet'!I81,"") | ... U81: =IF('G2 MT Reading Scoresheet'!U81<>"",'G2 MT Reading Scoresheet'!U81,"") | Y81: =IF(C81<>"",R81/6,"")
... A109: =A108+1 -> 99 | B109: =IF('G2 MT Reading Scoresheet'!B109<>"",'G2 MT Reading Scoresheet'!B109,"") | C109: =IF('G2 MT Reading Scoresheet'!C109<>"",'G2 MT Reading Scoresheet'!C109,"") | D109: =IF('G2 MT Reading Scoresheet'!D109<>"",'G2 MT Reading Scoresheet'!D109,"") | E109: =IF('G2 MT Reading Scoresheet'!E109<>"",'G2 MT Reading Scoresheet'!E109,"") | F109: =IF('G2 MT Reading Scoresheet'!F109<>"",'G2 MT Reading Scoresheet'!F109,"") | G109: =IF('G2 MT Reading Scoresheet'!G109<>"",'G2 MT Reading Scoresheet'!G109,"") | H109: =IF('G2 MT Reading Scoresheet'!H109<>"",'G2 MT Reading Scoresheet'!H109,"") | I109: =IF('G2 MT Reading Scoresheet'!I109<>"",'G2 MT Reading Scoresheet'!I109,"") | ... U109: =IF('G2 MT Reading Scoresheet'!U109<>"",'G2 MT Reading Scoresheet'!U109,"") | Y109: =IF(C109<>"",R109/6,"")
A110: 100 | B110: =IF('G2 MT Reading Scoresheet'!B110<>"",'G2 MT Reading Scoresheet'!B110,"") | C110: =IF('G2 MT Reading Scoresheet'!C110<>"",'G2 MT Reading Scoresheet'!C110,"") | D110: =IF('G2 MT Reading Scoresheet'!D110<>"",'G2 MT Reading Scoresheet'!D110,"") | E110: =IF('G2 MT Reading Scoresheet'!E110<>"",'G2 MT Reading Scoresheet'!E110,"") | F110: =IF('G2 MT Reading Scoresheet'!F110<>"",'G2 MT Reading Scoresheet'!F110,"") | G110: =IF('G2 MT Reading Scoresheet'!G110<>"",'G2 MT Reading Scoresheet'!G110,"") | H110: =IF('G2 MT Reading Scoresheet'!H110<>"",'G2 MT Reading Scoresheet'!H110,"") | I110: =IF('G2 MT Reading Scoresheet'!I110<>"",'G2 MT Reading Scoresheet'!I110,"") | ... U110: =IF('G2 MT Reading Scoresheet'!U110<>"",'G2 MT Reading Scoresheet'!U110,"") | Y110: =IF(C110<>"",R110/6,"")

Sheet Class Record
A1: CRLA3v1
A5: School: | C5: ='G2 MT Reading Scoresheet'!$C$5 -> 0 | E5: GRADE 2 Reading Assessment CLASS RECORD
A6: Teacher: | C6: ='G2 MT Reading Scoresheet'!C6 -> 0 | E6: =CONCATENATE("MOTHER TONGUE","(",'G2 MT Reading Scoresheet'!C9,")") -> MOTHER TONGUE(Tagalog) | K6: FILIPINO | Q6: Remarks
A7: Grade: | C7: Grade 1 | E7: Assessment Part 1 | G7: Assessment Part 2 | J7: READING PROFILE | K7: Assessment Part 1 | M7: Assessment Part 2
A8: S/N | B8: LRN | C8: Name of Learner | D8: Sex | E8: Assessment Part 1 Reading Level | F8: % of Total Score | G8: Reading Fluency | H8: Reading Comprehension | I8: Average Word Per Minute | K8: Assessment Part 1 Reading Level | L8: % of Total Score | M8: Reading Fluency | N8: Reading Comprehension | O8: Average Word Per Minute | P8: READING PROFILE
A9: 1 | B9: =IF('G2 MT Reading Scoresheet'!B11<>"",'G2 MT Reading Scoresheet'!B11,"") | C9: =IF('G2 MT Reading Scoresheet'!C11<>"",'G2 MT Reading Scoresheet'!C11,"") | D9: =IF('G2 MT Reading Scoresheet'!D11<>"",'G2 MT Reading Scoresheet'!D11,"") | E9: ='G2 MT Reading Scoresheet'!$J11 | F9: =IF(C9<>"",'G2 MT Reading Scoresheet'!$I11/30,"") | G9: =IF(AND($C9<>"",$E9<>"Full Refresher"),'G2 MT Reading Scoresheet'!$Q11,"") | H9: =IF(AND(C9<>"",E9<>"Full Refresher"),'G2 MT Reading Scoresheet'!$R11/6,"") | I9: =IF(AND(C9<>"",F9<>"Full Refresher"),'G2 MT Reading Scoresheet'!$P11,"") | J9: ='G2 MT Reading Scoresheet'!$U11 | K9: ='G2 FIL Reading Scoresheet'!$J11 | L9: =IF($C9<>"",'G2 FIL Reading Scoresheet'!$I11/30,"") | M9: =IF(AND($C9<>"",$K9<>"Full Refresher"),'G2 FIL Reading Scoresheet'!$Q11,"") | N9: =IF(AND($C9<>"",K9<>"Full Refresher"),'G2 FIL Reading Scoresheet'!$R11/6,"") | O9: =IF(AND(C9<>"",K9<>"Full Refresher"),'G2 FIL Reading Scoresheet'!$P11,"") | P9: ='G2 FIL Reading Scoresheet'!$U11 | Q9: =CONCATENATE(IF(ISBLANK('G2 MT Reading Scoresheet'!V11),"",CONCATENATE("MT:",TRIM('G2 MT Reading Scoresheet'!V11)))," ",IF(ISBLANK('G2 FIL Reading Scoresheet'!V11),"",CONCATENATE("FIL:",TRIM('G2 FIL Reading Scoresheet'!V11))))
A10: 2 | B10: =IF('G2 MT Reading Scoresheet'!B12<>"",'G2 MT Reading Scoresheet'!B12,"") | C10: =IF('G2 MT Reading Scoresheet'!C12<>"",'G2 MT Reading Scoresheet'!C12,"") | D10: =IF('G2 MT Reading Scoresheet'!D12<>"",'G2 MT Reading Scoresheet'!D12,"") | E10: ='G2 MT Reading Scoresheet'!$J12 | F10: =IF(C10<>"",'G2 MT Reading Scoresheet'!$I12/30,"") | G10: =IF(AND($C10<>"",$E10<>"Full Refresher"),'G2 MT Reading Scoresheet'!$Q12,"") | H10: =IF(AND(C10<>"",E10<>"Full Refresher"),'G2 MT Reading Scoresheet'!$R12/6,"") | I10: =IF(AND(D10<>"",F10<>"Full Refresher"),'G2 MT Reading Scoresheet'!$P12,"") | J10: ='G2 MT Reading Scoresheet'!$U12 | K10: ='G2 FIL Reading Scoresheet'!$J12 | L10: =IF($C10<>"",'G2 FIL Reading Scoresheet'!$I12/30,"") | M10: =IF(AND($C10<>"",$K10<>"Full Refresher"),'G2 FIL Reading Scoresheet'!$Q12,"") | N10: =IF(AND($C10<>"",K10<>"Full Refresher"),'G2 FIL Reading Scoresheet'!$R12/6,"") | O10: =IF(AND(C10<>"",K10<>"Full Refresher"),'G2 FIL Reading Scoresheet'!$P12,"") | P10: ='G2 FIL Reading Scoresheet'!$U12 | Q10: =CONCATENATE(IF(ISBLANK('G2 MT Reading Scoresheet'!V12),"",CONCATENATE("MT:",TRIM('G2 MT Reading Scoresheet'!V12)))," ",IF(ISBLANK('G2 FIL Reading Scoresheet'!V12),"",CONCATENATE("FIL:",TRIM('G2 FIL Reading Scoresheet'!V12))))
A11: 3 | B11: =IF('G2 MT Reading Scoresheet'!B13<>"",'G2 MT Reading Scoresheet'!B13,"") | C11: =IF('G2 MT Reading Scoresheet'!C13<>"",'G2 MT Reading Scoresheet'!C13,"") | D11: =IF('G2 MT Reading Scoresheet'!D13<>"",'G2 MT Reading Scoresheet'!D13,"") | E11: ='G2 MT Reading Scoresheet'!$J13 | F11: =IF(C11<>"",'G2 MT Reading Scoresheet'!$I13/30,"") | G11: =IF(AND($C11<>"",$E11<>"Full Refresher"),'G2 MT Reading Scoresheet'!$Q13,"") | H11: =IF(AND(C11<>"",E11<>"Full Refresher"),'G2 MT Reading Scoresheet'!$R13/6,"") | I11: =IF(AND(D11<>"",F11<>"Full Refresher"),'G2 MT Reading Scoresheet'!$P13,"") | J11: ='G2 MT Reading Scoresheet'!$U13 | K11: ='G2 FIL Reading Scoresheet'!$J13 | L11: =IF($C11<>"",'G2 FIL Reading Scoresheet'!$I13/30,"") | M11: =IF(AND($C11<>"",$K11<>"Full Refresher"),'G2 FIL Reading Scoresheet'!$Q13,"") | N11: =IF(AND($C11<>"",K11<>"Full Refresher"),'G2 FIL Reading Scoresheet'!$R13/6,"") | O11: =IF(AND(C11<>"",K11<>"Full Refresher"),'G2 FIL Reading Scoresheet'!$P13,"") | P11: ='G2 FIL Reading Scoresheet'!$U13 | Q11: =CONCATENATE(IF(ISBLANK('G2 MT Reading Scoresheet'!V13),"",CONCATENATE("MT:",TRIM('G2 MT Reading Scoresheet'!V13)))," ",IF(ISBLANK('G2 FIL Reading Scoresheet'!V13),"",CONCATENATE("FIL:",TRIM('G2 FIL Reading Scoresheet'!V13))))
A12: 4 | B12: =IF('G2 MT Reading Scoresheet'!B14<>"",'G2 MT Reading Scoresheet'!B14,"") | C12: =IF('G2 MT Reading Scoresheet'!C14<>"",'G2 MT Reading Scoresheet'!C14,"") | D12: =IF('G2 MT Reading Scoresheet'!D14<>"",'G2 MT Reading Scoresheet'!D14,"") | E12: ='G2 MT Reading Scoresheet'!$J14 | F12: =IF(C12<>"",'G2 MT Reading Scoresheet'!$I14/30,"") | G12: =IF(AND($C12<>"",$E12<>"Full Refresher"),'G2 MT Reading Scoresheet'!$Q14,"") | H12: =IF(AND(C12<>"",E12<>"Full Refresher"),'G2 MT Reading Scoresheet'!$R14/6,"") | I12: =IF(AND(D12<>"",F12<>"Full Refresher"),'G2 MT Reading Scoresheet'!$P14,"") | J12: ='G2 MT Reading Scoresheet'!$U14 | K12: ='G2 FIL Reading Scoresheet'!$J14 | L12: =IF($C12<>"",'G2 FIL Reading Scoresheet'!$I14/30,"") | M12: =IF(AND($C12<>"",$K12<>"Full Refresher"),'G2 FIL Reading Scoresheet'!$Q14,"") | N12: =IF(AND($C12<>"",K12<>"Full Refresher"),'G2 FIL Reading Scoresheet'!$R14/6,"") | O12: =IF(AND(C12<>"",K12<>"Full Refresher"),'G2 FIL Reading Scoresheet'!$P14,"") | P12: ='G2 FIL Reading Scoresheet'!$U14 | Q12: =CONCATENATE(IF(ISBLANK('G2 MT Reading Scoresheet'!V14),"",CONCATENATE("MT:",TRIM('G2 MT Reading Scoresheet'!V14)))," ",IF(ISBLANK('G2 FIL Reading Scoresheet'!V14),"",CONCATENATE("FIL:",TRIM('G2 FIL Reading Scoresheet'!V14))))
A13: 5 | B13: =IF('G2 MT Reading Scoresheet'!B15<>"",'G2 MT Reading Scoresheet'!B15,"") | C13: =IF('G2 MT Reading Scoresheet'!C15<>"",'G2 MT Reading Scoresheet'!C15,"") | D13: =IF('G2 MT Reading Scoresheet'!D15<>"",'G2 MT Reading Scoresheet'!D15,"") | E13: ='G2 MT Reading Scoresheet'!$J15 | F13: =IF(C13<>"",'G2 MT Reading Scoresheet'!$I15/30,"") | G13: =IF(AND($C13<>"",$E13<>"Full Refresher"),'G2 MT Reading Scoresheet'!$Q15,"") | H13: =IF(AND(C13<>"",E13<>"Full Refresher"),'G2 MT Reading Scoresheet'!$R15/6,"") | I13: =IF(AND(D13<>"",F13<>"Full Refresher"),'G2 MT Reading Scoresheet'!$P15,"") | J13: ='G2 MT Reading Scoresheet'!$U15 | K13: ='G2 FIL Reading Scoresheet'!$J15 | L13: =IF($C13<>"",'G2 FIL Reading Scoresheet'!$I15/30,"") | M13: =IF(AND($C13<>"",$K13<>"Full Refresher"),'G2 FIL Reading Scoresheet'!$Q15,"") | N13: =IF(AND($C13<>"",K13<>"Full Refresher"),'G2 FIL Reading Scoresheet'!$R15/6,"") | O13: =IF(AND(C13<>"",K13<>"Full Refresher"),'G2 FIL Reading Scoresheet'!$P15,"") | P13: ='G2 FIL Reading Scoresheet'!$U15 | Q13: =CONCATENATE(IF(ISBLANK('G2 MT Reading Scoresheet'!V15),"",CONCATENATE("MT:",TRIM('G2 MT Reading Scoresheet'!V15)))," ",IF(ISBLANK('G2 FIL Reading Scoresheet'!V15),"",CONCATENATE("FIL:",TRIM('G2 FIL Reading Scoresheet'!V15))))
A14: 6 | B14: =IF('G2 MT Reading Scoresheet'!B16<>"",'G2 MT Reading Scoresheet'!B16,"") | C14: =IF('G2 MT Reading Scoresheet'!C16<>"",'G2 MT Reading Scoresheet'!C16,"") | D14: =IF('G2 MT Reading Scoresheet'!D16<>"",'G2 MT Reading Scoresheet'!D16,"") | E14: ='G2 MT Reading Scoresheet'!$J16 | F14: =IF(C14<>"",'G2 MT Reading Scoresheet'!$I16/30,"") | G14: =IF(AND($C14<>"",$E14<>"Full Refresher"),'G2 MT Reading Scoresheet'!$Q16,"") | H14: =IF(AND(C14<>"",E14<>"Full Refresher"),'G2 MT Reading Scoresheet'!$R16/6,"") | I14: =IF(AND(D14<>"",F14<>"Full Refresher"),'G2 MT Reading Scoresheet'!$P16,"") | J14: ='G2 MT Reading Scoresheet'!$U16 | K14: ='G2 FIL Reading Scoresheet'!$J16 | L14: =IF($C14<>"",'G2 FIL Reading Scoresheet'!$I16/30,"") | M14: =IF(AND($C14<>"",$K14<>"Full Refresher"),'G2 FIL Reading Scoresheet'!$Q16,"") | N14: =IF(AND($C14<>"",K14<>"Full Refresher"),'G2 FIL Reading Scoresheet'!$R16/6,"") | O14: =IF(AND(C14<>"",K14<>"Full Refresher"),'G2 FIL Reading Scoresheet'!$P16,"") | P14: ='G2 FIL Reading Scoresheet'!$U16 | Q14: =CONCATENATE(IF(ISBLANK('G2 MT Reading Scoresheet'!V16),"",CONCATENATE("MT:",TRIM('G2 MT Reading Scoresheet'!V16)))," ",IF(ISBLANK('G2 FIL Reading Scoresheet'!V16),"",CONCATENATE("FIL:",TRIM('G2 FIL Reading Scoresheet'!V16))))
A15: 7 | B15: =IF('G2 MT Reading Scoresheet'!B17<>"",'G2 MT Reading Scoresheet'!B17,"") | C15: =IF('G2 MT Reading Scoresheet'!C17<>"",'G2 MT Reading Scoresheet'!C17,"") | D15: =IF('G2 MT Reading Scoresheet'!D17<>"",'G2 MT Reading Scoresheet'!D17,"") | E15: ='G2 MT Reading Scoresheet'!$J17 | F15: =IF(C15<>"",'G2 MT Reading Scoresheet'!$I17/30,"") | G15: =IF(AND($C15<>"",$E15<>"Full Refresher"),'G2 MT Reading Scoresheet'!$Q17,"") | H15: =IF(AND(C15<>"",E15<>"Full Refresher"),'G2 MT Reading Scoresheet'!$R17/6,"") | I15: =IF(AND(D15<>"",F15<>"Full Refresher"),'G2 MT Reading Scoresheet'!$P17,"") | J15: ='G2 MT Reading Scoresheet'!$U17 | K15: ='G2 FIL Reading Scoresheet'!$J17 | L15: =IF($C15<>"",'G2 FIL Reading Scoresheet'!$I17/30,"") | M15: =IF(AND($C15<>"",$K15<>"Full Refresher"),'G2 FIL Reading Scoresheet'!$Q17,"") | N15: =IF(AND($C15<>"",K15<>"Full Refresher"),'G2 FIL Reading Scoresheet'!$R17/6,"") | O15: =IF(AND(C15<>"",K15<>"Full Refresher"),'G2 FIL Reading Scoresheet'!$P17,"") | P15: ='G2 FIL Reading Scoresheet'!$U17 | Q15: =CONCATENATE(IF(ISBLANK('G2 MT Reading Scoresheet'!V17),"",CONCATENATE("MT:",TRIM('G2 MT Reading Scoresheet'!V17)))," ",IF(ISBLANK('G2 FIL Reading Scoresheet'!V17),"",CONCATENATE("FIL:",TRIM('G2 FIL Reading Scoresheet'!V17))))
A16: 8 | B16: =IF('G2 MT Reading Scoresheet'!B18<>"",'G2 MT Reading Scoresheet'!B18,"") | C16: =IF('G2 MT Reading Scoresheet'!C18<>"",'G2 MT Reading Scoresheet'!C18,"") | D16: =IF('G2 MT Reading Scoresheet'!D18<>"",'G2 MT Reading Scoresheet'!D18,"") | E16: ='G2 MT Reading Scoresheet'!$J18 | F16: =IF(C16<>"",'G2 MT Reading Scoresheet'!$I18/30,"") | G16: =IF(AND($C16<>"",$E16<>"Full Refresher"),'G2 MT Reading Scoresheet'!$Q18,"") | H16: =IF(AND(C16<>"",E16<>"Full Refresher"),'G2 MT Reading Scoresheet'!$R18/6,"") | I16: =IF(AND(D16<>"",F16<>"Full Refresher"),'G2 MT Reading Scoresheet'!$P18,"") | J16: ='G2 MT Reading Scoresheet'!$U18 | K16: ='G2 FIL Reading Scoresheet'!$J18 | L16: =IF($C16<>"",'G2 FIL Reading Scoresheet'!$I18/30,"") | M16: =IF(AND($C16<>"",$K16<>"Full Refresher"),'G2 FIL Reading Scoresheet'!$Q18,"") | N16: =IF(AND($C16<>"",K16<>"Full Refresher"),'G2 FIL Reading Scoresheet'!$R18/6,"") | O16: =IF(AND(C16<>"",K16<>"Full Refresher"),'G2 FIL Reading Scoresheet'!$P18,"") | P16: ='G2 FIL Reading Scoresheet'!$U18 | Q16: =CONCATENATE(IF(ISBLANK('G2 MT Reading Scoresheet'!V18),"",CONCATENATE("MT:",TRIM('G2 MT Reading Scoresheet'!V18)))," ",IF(ISBLANK('G2 FIL Reading Scoresheet'!V18),"",CONCATENATE("FIL:",TRIM('G2 FIL Reading Scoresheet'!V18))))
A17: 9 | B17: =IF('G2 MT Reading Scoresheet'!B19<>"",'G2 MT Reading Scoresheet'!B19,"") | C17: =IF('G2 MT Reading Scoresheet'!C19<>"",'G2 MT Reading Scoresheet'!C19,"") | D17: =IF('G2 MT Reading Scoresheet'!D19<>"",'G2 MT Reading Scoresheet'!D19,"") | E17: ='G2 MT Reading Scoresheet'!$J19 | F17: =IF(C17<>"",'G2 MT Reading Scoresheet'!$I19/30,"") | G17: =IF(AND($C17<>"",$E17<>"Full Refresher"),'G2 MT Reading Scoresheet'!$Q19,"") | H17: =IF(AND(C17<>"",E17<>"Full Refresher"),'G2 MT Reading Scoresheet'!$R19/6,"") | I17: =IF(AND(D17<>"",F17<>"Full Refresher"),'G2 MT Reading Scoresheet'!$P19,"") | J17: ='G2 MT Reading Scoresheet'!$U19 | K17: ='G2 FIL Reading Scoresheet'!$J19 | L17: =IF($C17<>"",'G2 FIL Reading Scoresheet'!$I19/30,"") | M17: =IF(AND($C17<>"",$K17<>"Full Refresher"),'G2 FIL Reading Scoresheet'!$Q19,"") | N17: =IF(AND($C17<>"",K17<>"Full Refresher"),'G2 FIL Reading Scoresheet'!$R19/6,"") | O17: =IF(AND(C17<>"",K17<>"Full Refresher"),'G2 FIL Reading Scoresheet'!$P19,"") | P17: ='G2 FIL Reading Scoresheet'!$U19 | Q17: =CONCATENATE(IF(ISBLANK('G2 MT Reading Scoresheet'!V19),"",CONCATENATE("MT:",TRIM('G2 MT Reading Scoresheet'!V19)))," ",IF(ISBLANK('G2 FIL Reading Scoresheet'!V19),"",CONCATENATE("FIL:",TRIM('G2 FIL Reading Scoresheet'!V19))))
